********************* [2024.11.19-08:34:36] *********************

Running linting...
0
0

********************* [2024.11.19-08:32:22] *********************

Running linting...
0
0

********************* [2024.11.19-08:24:09] *********************

Running linting...
0
0

********************* [2024.11.19-08:21:06] *********************

Running linting...
0
0

********************* [2024.11.19-08:18:12] *********************

Running linting...
0
0

********************* [2024.11.19-08:15:52] *********************

Running linting...
0
0

********************* [2024.11.19-08:15:31] *********************

Running linting...
0
./tests/test_routes.py:75:5: E303 too many blank lines (2)
./tests/test_routes.py:79:5: E301 expected 1 blank line, found 0
1     E301 expected 1 blank line, found 0
1     E303 too many blank lines (2)
2
make: *** [Makefile:50: lint] Error 1

********************* [2024.11.19-08:14:56] *********************

Running linting...
0
./tests/test_routes.py:26:1: E302 expected 2 blank lines, found 1
./tests/test_routes.py:54:5: E303 too many blank lines (2)
./tests/test_routes.py:58:5: E301 expected 1 blank line, found 0
./tests/test_routes.py:75:5: E303 too many blank lines (2)
./tests/test_routes.py:79:5: E301 expected 1 blank line, found 0
2     E301 expected 1 blank line, found 0
1     E302 expected 2 blank lines, found 1
2     E303 too many blank lines (2)
5
make: *** [Makefile:50: lint] Error 1

********************* [2024.11.19-08:14:14] *********************

Running linting...
0
./tests/test_routes.py:26:1: E302 expected 2 blank lines, found 1
1     E302 expected 2 blank lines, found 1
1
make: *** [Makefile:50: lint] Error 1

********************* [2024.11.19-08:12:27] *********************

Running linting...
0
./service/__init__.py:9:1: E265 block comment should start with '# '
./tests/test_routes.py:26:1: E302 expected 2 blank lines, found 1
./tests/test_routes.py:201:63: W292 no newline at end of file
1     E265 block comment should start with '# '
1     E302 expected 2 blank lines, found 1
1     W292 no newline at end of file
3
make: *** [Makefile:50: lint] Error 1

********************* [2024.11.18-10:59:41] *********************

Running linting...
0
0

********************* [2024.11.18-10:58:54] *********************

Running linting...
0
./tests/test_error_handlers.py:50:5: E303 too many blank lines (2)
./tests/test_error_handlers.py:53:79: W292 no newline at end of file
1     E303 too many blank lines (2)
1     W292 no newline at end of file
2
make: *** [Makefile:50: lint] Error 1

********************* [2024.11.18-10:57:09] *********************

Running linting...
0
./tests/test_error_handlers.py:8:1: F401 'tests.factories.AccountFactory' imported but unused
./tests/test_error_handlers.py:51:5: E303 too many blank lines (2)
./tests/test_error_handlers.py:54:79: W292 no newline at end of file
1     E303 too many blank lines (2)
1     F401 'tests.factories.AccountFactory' imported but unused
1     W292 no newline at end of file
3
make: *** [Makefile:50: lint] Error 1

********************* [2024.11.18-10:43:13] *********************

Running linting...
0
0

********************* [2024.11.18-10:37:07] *********************

Running linting...
0
0

********************* [2024.11.18-10:29:46] *********************

Running linting...
0
0

********************* [2024.11.18-10:18:05] *********************

Running linting...
0
./tests/test_routes.py:188:39: W292 no newline at end of file
1     W292 no newline at end of file
1
make: *** [Makefile:50: lint] Error 1

********************* [2024.11.18-10:04:45] *********************

Running linting...
0
0

********************* [2024.11.18-10:01:13] *********************

Running linting...
0
0

********************* [2024.11.18-10:00:27] *********************

Running linting...
0
./tests/test_routes.py:180:74: W292 no newline at end of file
1     W292 no newline at end of file
1
make: *** [Makefile:50: lint] Error 1

********************* [2024.11.18-09:39:27] *********************

Running linting...
0
0

********************* [2024.11.18-09:38:00] *********************

Running linting...
0
0

********************* [2024.11.18-09:35:32] *********************

Running linting...
0
0

********************* [2024.11.18-09:34:36] *********************

Running linting...
0
0

********************* [2024.11.18-09:33:16] *********************

Running linting...
0
./service/routes.py:88:1: E302 expected 2 blank lines, found 1
./service/routes.py:104:1: W293 blank line contains whitespace
1     E302 expected 2 blank lines, found 1
1     W293 blank line contains whitespace
2
make: *** [Makefile:50: lint] Error 1

********************* [2024.11.18-09:32:56] *********************

Running linting...
0
./service/routes.py:87:1: E302 expected 2 blank lines, found 1
./service/routes.py:103:1: W293 blank line contains whitespace
1     E302 expected 2 blank lines, found 1
1     W293 blank line contains whitespace
2
make: *** [Makefile:50: lint] Error 1

********************* [2024.11.18-09:31:25] *********************

Running linting...
0
./service/routes.py:87:1: E302 expected 2 blank lines, found 1
./service/routes.py:102:1: W293 blank line contains whitespace
1     E302 expected 2 blank lines, found 1
1     W293 blank line contains whitespace
2
make: *** [Makefile:50: lint] Error 1

********************* [2024.11.18-09:30:22] *********************

Running linting...
0
./service/routes.py:87:1: E302 expected 2 blank lines, found 1
./service/routes.py:97:1: W293 blank line contains whitespace
./service/routes.py:102:1: W293 blank line contains whitespace
1     E302 expected 2 blank lines, found 1
2     W293 blank line contains whitespace
3
make: *** [Makefile:50: lint] Error 1

********************* [2024.11.18-09:24:31] *********************

Running linting...
0
./tests/test_routes.py:158:80: W292 no newline at end of file
1     W292 no newline at end of file
1
make: *** [Makefile:50: lint] Error 1

********************* [2024.11.18-08:40:26] *********************

Running linting...
0
0

********************* [2024.11.18-08:38:48] *********************

Running linting...
0
0

********************* [2024.11.18-08:29:11] *********************

Running linting...
0
0

********************* [2024.11.18-08:18:12] *********************

Running linting...
0
0

********************* [2024.11.18-08:06:35] *********************

Running linting...
0
0

********************* [2024.11.18-08:06:11] *********************

Running linting...
0
0

********************* [2024.11.18-08:04:48] *********************

Running linting...
0
0

********************* [2024.11.18-07:57:50] *********************

Running linting...
0
0

********************* [2024.11.18-07:54:18] *********************

Running linting...
0
./tests/test_routes.py:139:74: W292 no newline at end of file
1     W292 no newline at end of file
1
make: *** [Makefile:50: lint] Error 1

********************* [2024.11.18-07:50:45] *********************

Running linting...
0
./service/routes.py:77:1: W293 blank line contains whitespace
./tests/test_routes.py:134:58: W292 no newline at end of file
1     W292 no newline at end of file
1     W293 blank line contains whitespace
2
make: *** [Makefile:50: lint] Error 1

********************* [2024.11.18-06:49:31] *********************

Running linting...
0
0

********************* [2024.11.18-06:48:41] *********************

Running linting...
Traceback (most recent call last):
  File "/home/theia/venv/bin/flake8", line 8, in <module>
    sys.exit(main())
  File "/home/theia/venv/lib/python3.9/site-packages/flake8/main/cli.py", line 22, in main
    app.run(argv)
  File "/home/theia/venv/lib/python3.9/site-packages/flake8/main/application.py", line 375, in run
    self._run(argv)
  File "/home/theia/venv/lib/python3.9/site-packages/flake8/main/application.py", line 363, in _run
    self.initialize(argv)
  File "/home/theia/venv/lib/python3.9/site-packages/flake8/main/application.py", line 343, in initialize
    self.find_plugins(config_finder)
  File "/home/theia/venv/lib/python3.9/site-packages/flake8/main/application.py", line 153, in find_plugins
    local_plugins = config.get_local_plugins(config_finder)
  File "/home/theia/venv/lib/python3.9/site-packages/flake8/options/config.py", line 289, in get_local_plugins
    config, config_files = config_finder.local_configs_with_files()
  File "/home/theia/venv/lib/python3.9/site-packages/flake8/options/config.py", line 126, in local_configs_with_files
    config, found_files = self._read_config(*self.local_config_files())
  File "/home/theia/venv/lib/python3.9/site-packages/flake8/options/config.py", line 66, in _read_config
    found_files.extend(config.read(filename))
  File "/usr/lib/python3.9/configparser.py", line 697, in read
    self._read(fp, filename)
  File "/usr/lib/python3.9/configparser.py", line 1070, in _read
    raise DuplicateSectionError(sectname, fpname,
configparser.DuplicateSectionError: While reading from '/home/project/devops-capstone-project/setup.cfg' [line 14]: section 'nosetests' already exists
make: *** [Makefile:49: lint] Error 1

