********************* [2024.11.18-06:49:31] *********************

Running linting...
0
0

********************* [2024.11.18-06:48:41] *********************

Running linting...
Traceback (most recent call last):
  File "/home/theia/venv/bin/flake8", line 8, in <module>
    sys.exit(main())
  File "/home/theia/venv/lib/python3.9/site-packages/flake8/main/cli.py", line 22, in main
    app.run(argv)
  File "/home/theia/venv/lib/python3.9/site-packages/flake8/main/application.py", line 375, in run
    self._run(argv)
  File "/home/theia/venv/lib/python3.9/site-packages/flake8/main/application.py", line 363, in _run
    self.initialize(argv)
  File "/home/theia/venv/lib/python3.9/site-packages/flake8/main/application.py", line 343, in initialize
    self.find_plugins(config_finder)
  File "/home/theia/venv/lib/python3.9/site-packages/flake8/main/application.py", line 153, in find_plugins
    local_plugins = config.get_local_plugins(config_finder)
  File "/home/theia/venv/lib/python3.9/site-packages/flake8/options/config.py", line 289, in get_local_plugins
    config, config_files = config_finder.local_configs_with_files()
  File "/home/theia/venv/lib/python3.9/site-packages/flake8/options/config.py", line 126, in local_configs_with_files
    config, found_files = self._read_config(*self.local_config_files())
  File "/home/theia/venv/lib/python3.9/site-packages/flake8/options/config.py", line 66, in _read_config
    found_files.extend(config.read(filename))
  File "/usr/lib/python3.9/configparser.py", line 697, in read
    self._read(fp, filename)
  File "/usr/lib/python3.9/configparser.py", line 1070, in _read
    raise DuplicateSectionError(sectname, fpname,
configparser.DuplicateSectionError: While reading from '/home/project/devops-capstone-project/setup.cfg' [line 14]: section 'nosetests' already exists
make: *** [Makefile:49: lint] Error 1

