********************* [2024.11.18-10:04:45] *********************

Running linting...
0
0

********************* [2024.11.18-10:01:13] *********************

Running linting...
0
0

********************* [2024.11.18-10:00:27] *********************

Running linting...
0
./tests/test_routes.py:180:74: W292 no newline at end of file
1     W292 no newline at end of file
1
make: *** [Makefile:50: lint] Error 1

********************* [2024.11.18-09:39:27] *********************

Running linting...
0
0

********************* [2024.11.18-09:38:00] *********************

Running linting...
0
0

********************* [2024.11.18-09:35:32] *********************

Running linting...
0
0

********************* [2024.11.18-09:34:36] *********************

Running linting...
0
0

********************* [2024.11.18-09:33:16] *********************

Running linting...
0
./service/routes.py:88:1: E302 expected 2 blank lines, found 1
./service/routes.py:104:1: W293 blank line contains whitespace
1     E302 expected 2 blank lines, found 1
1     W293 blank line contains whitespace
2
make: *** [Makefile:50: lint] Error 1

********************* [2024.11.18-09:32:56] *********************

Running linting...
0
./service/routes.py:87:1: E302 expected 2 blank lines, found 1
./service/routes.py:103:1: W293 blank line contains whitespace
1     E302 expected 2 blank lines, found 1
1     W293 blank line contains whitespace
2
make: *** [Makefile:50: lint] Error 1

********************* [2024.11.18-09:31:25] *********************

Running linting...
0
./service/routes.py:87:1: E302 expected 2 blank lines, found 1
./service/routes.py:102:1: W293 blank line contains whitespace
1     E302 expected 2 blank lines, found 1
1     W293 blank line contains whitespace
2
make: *** [Makefile:50: lint] Error 1

********************* [2024.11.18-09:30:22] *********************

Running linting...
0
./service/routes.py:87:1: E302 expected 2 blank lines, found 1
./service/routes.py:97:1: W293 blank line contains whitespace
./service/routes.py:102:1: W293 blank line contains whitespace
1     E302 expected 2 blank lines, found 1
2     W293 blank line contains whitespace
3
make: *** [Makefile:50: lint] Error 1

********************* [2024.11.18-09:24:31] *********************

Running linting...
0
./tests/test_routes.py:158:80: W292 no newline at end of file
1     W292 no newline at end of file
1
make: *** [Makefile:50: lint] Error 1

********************* [2024.11.18-08:40:26] *********************

Running linting...
0
0

********************* [2024.11.18-08:38:48] *********************

Running linting...
0
0

********************* [2024.11.18-08:29:11] *********************

Running linting...
0
0

********************* [2024.11.18-08:18:12] *********************

Running linting...
0
0

********************* [2024.11.18-08:06:35] *********************

Running linting...
0
0

********************* [2024.11.18-08:06:11] *********************

Running linting...
0
0

********************* [2024.11.18-08:04:48] *********************

Running linting...
0
0

********************* [2024.11.18-07:57:50] *********************

Running linting...
0
0

********************* [2024.11.18-07:54:18] *********************

Running linting...
0
./tests/test_routes.py:139:74: W292 no newline at end of file
1     W292 no newline at end of file
1
make: *** [Makefile:50: lint] Error 1

********************* [2024.11.18-07:50:45] *********************

Running linting...
0
./service/routes.py:77:1: W293 blank line contains whitespace
./tests/test_routes.py:134:58: W292 no newline at end of file
1     W292 no newline at end of file
1     W293 blank line contains whitespace
2
make: *** [Makefile:50: lint] Error 1

********************* [2024.11.18-06:49:31] *********************

Running linting...
0
0

********************* [2024.11.18-06:48:41] *********************

Running linting...
Traceback (most recent call last):
  File "/home/theia/venv/bin/flake8", line 8, in <module>
    sys.exit(main())
  File "/home/theia/venv/lib/python3.9/site-packages/flake8/main/cli.py", line 22, in main
    app.run(argv)
  File "/home/theia/venv/lib/python3.9/site-packages/flake8/main/application.py", line 375, in run
    self._run(argv)
  File "/home/theia/venv/lib/python3.9/site-packages/flake8/main/application.py", line 363, in _run
    self.initialize(argv)
  File "/home/theia/venv/lib/python3.9/site-packages/flake8/main/application.py", line 343, in initialize
    self.find_plugins(config_finder)
  File "/home/theia/venv/lib/python3.9/site-packages/flake8/main/application.py", line 153, in find_plugins
    local_plugins = config.get_local_plugins(config_finder)
  File "/home/theia/venv/lib/python3.9/site-packages/flake8/options/config.py", line 289, in get_local_plugins
    config, config_files = config_finder.local_configs_with_files()
  File "/home/theia/venv/lib/python3.9/site-packages/flake8/options/config.py", line 126, in local_configs_with_files
    config, found_files = self._read_config(*self.local_config_files())
  File "/home/theia/venv/lib/python3.9/site-packages/flake8/options/config.py", line 66, in _read_config
    found_files.extend(config.read(filename))
  File "/usr/lib/python3.9/configparser.py", line 697, in read
    self._read(fp, filename)
  File "/usr/lib/python3.9/configparser.py", line 1070, in _read
    raise DuplicateSectionError(sectname, fpname,
configparser.DuplicateSectionError: While reading from '/home/project/devops-capstone-project/setup.cfg' [line 14]: section 'nosetests' already exists
make: *** [Makefile:49: lint] Error 1

